Workbook
Name __sor1: #REF!
Name __sor2: #REF!
Name __sor3: #REF!
Name __sor4: #REF!
Name __sor5: #REF!
Name __sor6: #REF!
Name __sor7: #REF!
Name __sor8: #REF!
Name __sor9: #REF!
Name _1PRINT_VAL1: [3]Macros!$A$2:$A$13
Name _2PRINT_VAL2: [3]Macros!$D$2:$D$13
Name _3PRINT_VAL3: [3]Macros!$G$2:$G$13
Name _4PRINT_VAL4: [3]Macros!$J$2:$J$13
Name _5PRINT_VAL5: [3]Macros!$M$2:$M$13
Name _6PRINT_VAL6: [3]Macros!$P$2:$P$13
Name _7PRINT_VAL7: [3]Macros!$S$2:$S$13
Name _8PRINT_VAL8: [3]Macros!$V$2:$V$13
Name _9PRINT_VAL9: [3]Macros!$Y$2:$Y$13
Name _sor1: #REF!
Name _sor2: #REF!
Name _sor3: #REF!
Name _sor4: #REF!
Name _sor5: #REF!
Name _sor6: #REF!
Name _sor7: #REF!
Name _sor8: #REF!
Name _sor9: #REF!
Name _VAL10: '[3]Valuation 10'!$A$1:$K$88
Name _VAL7: '[3]Valuation 7'!$A$1:$K$88
Name _VAL8: '[3]Valuation 8'!$A$1:$K$88
Name _VAL9: '[3]Valuation 9'!$A$1:$K$88
Name compaction: '[5]Land-based Equipment Library'!$C$159:$C$175
Name concretemixer: '[5]Land-based Equipment Library'!$C$183:$C$188
Name crawler: '[5]Land-based Equipment Library'!$C$12:$C$32
Name dumptrucks: '[5]Land-based Equipment Library'!$C$120:$C$132
Name excavators: '[5]Land-based Equipment Library'!$C$65:$C$88
Name General_Labourer: #REF!
Name here: '[6]6th form (E)'!#REF!
Name KeywordColumn: #REF!
Name Location1List: #REF!
Name Location2Column: #REF!
Name Location2Start: #REF!
Name Location3Column: #REF!
Name oldcoll: #REF!
Name piling: '[5]Land-based Equipment Library'!$C$246:$C$258
Name QS: #REF!
Name Target_Fee: '[7]Fees '!$G$13
Name tractors: '[5]Land-based Equipment Library'!$C$134:$C$157
Name TypeColumn: #REF!
Name TypeList: #REF!
Name TypeStart: #REF!

Sheet 2.0.1.Elemental Summary
F2: G-128 Alterations
F3: Concept Cost Plan
B5: 2.0 SUMMARY
B7: 2.0.1 Elemental Cost Plan Summary - Level 1 | H7: Previously
D8: GIFA | E8: 215 | F8: m2 | H8: 215 | I8: m2
B10: Ref | C10: Element | E10: Total £ | F10: £/m2 | H10: Total £ | I10: £/m2 | J10: Comments
B11: 0 | C11: Facilitating Works | E11: ='2.0.2.Elemental Summary'!E13 -> 65567 | F11: =E11/$E$8 -> 304.96279 | H11: 0 | I11: =H11/$H$8 -> 0
B12: 2 | C12: Superstructure | E12: ='2.0.2.Elemental Summary'!E16 -> 68690 | F12: =E12/$E$8 -> 319.48837 | H12: 0 | I12: =H12/$H$8 -> 0
B13: 3 | C13: Finishes | E13: ='2.0.2.Elemental Summary'!E20 -> 58898 | F13: =E13/$E$8 -> 273.94419 | H13: 0 | I13: =H13/$H$8 -> 0
B14: 4 | C14: Fittings, Furnishings and Equipment | E14: ='2.0.2.Elemental Summary'!E22 -> 765000 | F14: =E14/$E$8 -> 3558.1395 | H14: 0 | I14: =H14/$H$8 -> 0
B15: 5 | C15: Services | E15: ='2.0.2.Elemental Summary'!E31 -> 537573.75 | F15: =E15/$E$8 -> 2500.343 | H15: 0 | I15: =H15/$H$8 -> 0
C16: Facilitating and Building Works | E16: =E11+E12+E13+E14+E15 -> 1495728.8 | F16: =E16/$E$8 -> 6956.8779 | H16: =SUM(H11:H15) -> 0 | I16: =H16/$H$8 -> 0
B17: 9 | C17: Preliminaries (incl. Contractor's design) | E17: ='2.0.2.Elemental Summary'!E36 -> 362500 | F17: =E17/$E$8 -> 1686.0465 | H17: =H16*16% -> 0 | I17: =H17/$H$8 -> 0
B18: 10 | C18: Overheads and Profit | D18: 0.05 | E18: =(+E16+E17)*D18 -> 92911.438 | F18: =E18/$E$8 -> 432.14622 | H18: =(H16+H17)*6.5% -> 0 | I18: =H18/$H$8 -> 0 | J18: % adjustment
C19: Total Building Works Estimate | E19: =SUM(E16:E18) -> 1951140.2 | F19: =E19/$E$8 -> 9075.0706 | H19: =SUM(H16:H18) -> 0 | I19: =H19/$H$8 -> 0
B20: 11 | C20: Professional Services | E20: ='2.0.2.Elemental Summary'!E39 -> 141800 | F20: =E20/$E$8 -> 659.53488 | H20: 0 | I20: =H20/$H$8 -> 0
C21: SUB-TOTAL | E21: =SUM(E19:E20) -> 2092940.2 | F21: =E21/$E$8 -> 9734.6055 | H21: =SUM(H19:H20) -> 0 | I21: =H21/$H$8 -> 0
B22: 12 | C22: Equipment (supplied by the Client) | E22: ='2.0.2.Elemental Summary'!E41 -> 1975045 | F22: =E22/$E$8 -> 9186.2558 | H22: 0 | I22: =H22/$H$8 -> 0
C23: SUB-TOTAL | E23: =SUM(E21:E22) -> 4067985.2 | F23: =E23/$E$8 -> 18920.861 | H23: =SUM(H21:H22) -> 0 | I23: =H23/$H$8 -> 0
B24: 13.1 | C24: Design Development Risk (Refer to Risk Register) | E24: ='2.0.2.Elemental Summary'!E43 -> 397875 | F24: =E24/$E$8 -> 1850.5814 | H24: =H21*3% -> 0 | I24: =H24/$H$8 -> 0
B25: 13.2 | C25: Construction Risk | E25: incl above | H25: =H21*5% -> 0 | I25: =H25/$H$8 -> 0
C26: Risk Allowance Estimate | E26: =SUM(E24:E25) -> 397875 | F26: =E26/$E$8 -> 1850.5814 | H26: =SUM(H24:H25) -> 0 | I26: =H26/$H$8 -> 0
C27: COST LIMIT (excluding inflation) | E27: =E23+E26 -> 4465860.2 | F27: =E27/$E$8 -> 20771.443 | H27: =SUM(H21:H25) -> 0 | I27: =H27/$H$8 -> 0
B28: 14 | C28: Inflation | D28: 0.021537593 | E28: =E27*D28 -> 96183.881 | F28: =E28/$E$8 -> 447.36689 | H28: =H27*7.5% -> 0 | I28: =H28/$H$8 -> 0 | J28: % adjustment
C29: COST LIMIT (including inflation) | E29: =SUM(E27:E28) -> 4562044.1 | F29: =E29/$E$8 -> 21218.81 | H29: =SUM(H27:H28) -> 0 | I29: =H29/$H$8 -> 0
B30: 15 | C30: VAT | D30: Excluded | E30: 0 | F30: =E30/$E$8 -> 0 | H30: 0 | I30: =H30/$H$8 -> 0
C31: Total | E31: =SUM(E29:E30) -> 4562044.1 | F31: =E31/$E$8 -> 21218.81 | H31: =SUM(H29:H30) -> 0 | I31: =H31/$H$8 -> 0
C33: Construction | E33: =(E21-('2.0.2.4_FF&E'!G20+'2.0.2.4_FF&E'!G22))+((E21-('2.0.2.4_FF&E'!G20+'2.0.2.4_FF&E'!G22))*D28) -> 1422940.8
C34: Equipment | E34: =E22+('2.0.2.4_FF&E'!G20+'2.0.2.4_FF&E'!G22)+((E22+('2.0.2.4_FF&E'!G20+'2.0.2.4_FF&E'!G22))*D28) -> 2732659
C35: Risk | E35: =E26+(E26*D28) -> 406444.27
E36: =SUM(E33:E35) -> 4562044.1
C38: Construction Estimate Accuracy | D38: 0.2 | E38: =ROUND(E33+(E33*D38),-4) -> 1710000
D39: -0.1 | E39: =ROUND(E33+(E33*D39),-4) -> 1280000
C40: Equipment Estimate Accuracy | D40: 0.2 | E40: =ROUND(E34+(E34*D40),-4) -> 3280000
D41: -0.1 | E41: =ROUND(E34+(E34*D41),-4) -> 2460000
C42: Estimate Accuracy | D42: Upper Limit | E42: =E38+E40 -> 4990000
D43: Lower Limit | E43: =E39+E41 -> 3740000
H45: =E31-H31 -> 4562044.1 | I45: =H45/H31 -> #DIV/0!

Sheet 2.0.2.Elemental Summary
F2: G-128 Alterations | J2: Lab | K2: 181.8
F3: Concept Cost Plan | J3: Write up Up | K3: 33.3
J4: GIFA | K4: =SUM(K2:K3) -> 215.1
B5: 2.0 SUMMARY
B7: 2.0.2 Elemental Cost Plan Summary - Level 2
D8: GIFA | E8: 215 | F8: m2
B10: Ref | C10: Element | E10: Total £ | F10: £/m2
B11: 0.1 | C11: Strip Out, Alterations and Demolition (partitions and the like) | E11: ='2.0.2.0_Facilitating Works'!G34 -> 46967 | F11: =E11/$E$8 -> 218.45116
B12: 0.2 | C12: Strip Out (services) | E12: ='2.0.2.0_Facilitating Works'!G54 -> 18600 | F12: =E12/$E$8 -> 86.511628
B13: 0 | C13: Facilitating Works | E13: =SUM(E11:E12) -> 65567 | F13: =E13/$E$8 -> 304.96279
B14: 2.7 | C14: Internal Walls and Partitions | E14: ='2.0.2.2_Superstructure'!G22 -> 42440 | F14: =E14/$E$8 -> 197.39535
B15: 2.8 | C15: Internal doors | E15: ='2.0.2.2_Superstructure'!G34 -> 26250 | F15: =E15/$E$8 -> 122.09302
B16: 2 | C16: Superstructure | E16: =SUM(E14:E15) -> 68690 | F16: =E16/$E$8 -> 319.48837
B17: 3.1 | C17: Wall Finishes | E17: ='2.0.2.3_Finishes'!G18 -> 9810 | F17: =E17/$E$8 -> 45.627907
B18: 3.2 | C18: Floor Finishes | E18: ='2.0.2.3_Finishes'!G28 -> 23631 | F18: =E18/$E$8 -> 109.91163
B19: 3.3 | C19: Ceiling Finishes | E19: ='2.0.2.3_Finishes'!G38 -> 25457 | F19: =E19/$E$8 -> 118.40465
B20: 3 | C20: Finishes | E20: =SUM(E17:E19) -> 58898 | F20: =E20/$E$8 -> 273.94419
B21: 4.1 | C21: General fittings, furnishings and equipment | E21: ='2.0.2.4_FF&E'!G29 -> 765000 | F21: =E21/$E$8 -> 3558.1395
B22: 4 | C22: Fittings, Furnishings and Equipment | E22: =SUM(E21) -> 765000 | F22: =E22/$E$8 -> 3558.1395
B23: 5.3 | C23: Disposal installations | E23: ='2.0.2.5_Services'!G16 -> 3000 | F23: =E23/$E$8 -> 13.953488
B24: 5.4 | C24: Water installations | E24: ='2.0.2.5_Services'!G26 -> 38600 | F24: =E24/$E$8 -> 179.53488
B25: 5.6 | C25: Heating, Ventilation and Air Conditioning | E25: ='2.0.2.5_Services'!G40 -> 217920 | F25: =E25/$E$8 -> 1013.5814
B26: 5.8 | C26: Electrical installations | E26: ='2.0.2.5_Services'!G50 -> 107380 | F26: =E26/$E$8 -> 499.44186
B27: 5.11 | C27: Fire and lightning protection | E27: ='2.0.2.5_Services'!G56 -> 30030 | F27: =E27/$E$8 -> 139.67442
B28: 5.12 | C28: Communication, security and control systems | E28: ='2.0.2.5_Services'!G68 -> 51345 | F28: =E28/$E$8 -> 238.81395
B29: 5.13 | C29: Special installations | E29: ='2.0.2.5_Services'!G74 -> 63700 | F29: =E29/$E$8 -> 296.27907
B30: 5.14 | C30: Builder's Work in Connection with Services | E30: ='2.0.2.5_Services'!G80 -> 25598.75 | F30: =E30/$E$8 -> 119.06395
B31: 5 | C31: Services | E31: =SUM(E23:E30) -> 537573.75 | F31: =E31/$E$8 -> 2500.343
C32: Facilitating and Building Works | E32: =E13+E16+E20+E22+E31 -> 1495728.8 | F32: =E32/$E$8 -> 6956.8779
B33: 9.1 | C33: Temporary Works | E33: ='2.0.2.9 Prelims and Staff'!G18 -> 10500 | F33: =E33/$E$8 -> 48.837209
B34: 9.2 | C34: Site Welfare and Accommodation | E34: ='2.0.2.9 Prelims and Staff'!G24 -> 21000 | F34: =E34/$E$8 -> 97.674419
B35: 9.3 | C35: Design and Construction Management | E35: ='2.0.2.9 Prelims and Staff'!G38 -> 331000 | F35: =E35/$E$8 -> 1539.5349 | I35: =E35/E32 -> 0.22129681
B36: 9 | C36: Preliminaries (incl. Contractor's design) | E36: =SUM(E33:E35) -> 362500 | F36: =E36/$E$8 -> 1686.0465
B37: 10 | C37: Overheads and Profit | D37: 0.05 | E37: =(+E32+E36)*D37 -> 92911.438 | F37: =E37/$E$8 -> 432.14622
C38: Total Building Works Estimate | E38: =SUM(E32, E36:E37) -> 1951140.2 | F38: =E38/$E$8 -> 9075.0706
B39: 11 | C39: Professional Services | E39: ='2.0.2.11 Professional Services'!G30 -> 141800 | F39: =E39/$E$8 -> 659.53488 | I39: =E39/E38 -> 0.072675455
C40: SUB-TOTAL | E40: =SUM(E38:E39) -> 2092940.2 | F40: =E40/$E$8 -> 9734.6055
B41: 12 | C41: Equipment (supplied and installed by the Client) | E41: ='2.0.2.12 Client Equipment'!G18 -> 1975045 | F41: =E41/$E$8 -> 9186.2558
C42: SUB-TOTAL | E42: =SUM(E40:E41) -> 4067985.2 | F42: =E42/$E$8 -> 18920.861
B43: 13.1 | C43: Design Development Risk | E43: 397875 | F43: =E43/$E$8 -> 1850.5814
...

Sheet 2.0.2.0_Facilitating Works
G2: G-128 Alterations
G3: Concept Cost Plan
B5: 2.0.2.0 FACILITATING WORKS
B10: Item | C10: Description | D10: Qty | E10: Unit | F10: Rate | G10: Total
B12: 1 | C12: Strip Out, Alterations and Demolition (partitions and the like)
C14: Disconnect and remove antistatic plate adjacent to G128 entrance and set aside for possible re-use by Landlord | D14: 1 | E14: item | F14: 350 | G14: =D14*F14 -> 350
C16: General clearance of furniture and laboratory equipment | D16: 1 | E16: item | F16: 7000 | G16: =D16*F16 -> 7000
C18: Remove floor coverings, skirtings etc and dispose | D18: 180 | E18: m2 | F18: 24 | G18: =D18*F18 -> 4320
C20: Remove suspended ceiling and dispose | D20: 27 | E20: m2 | F20: 11 | G20: =D20*F20 -> 297
C22: Carefully remove existing door between G128 and G128D and set aside for re-use if required | D22: 1 | E22: item | F22: 350 | G22: =D22*F22 -> 350
C24: Carefully take down and remove existing blockwork wall between G128 and G128D and dispose | D24: 1 | E24: item | F24: 4500 | G24: =D24*F24 -> 4500
C26: Form openings through reinforced concrete wall for pass through hatch | D26: 2 | E26: nr | F26: 4500 | G26: =D26*F26 -> 9000
C28: Form openings through reinforced concrete wall for doorway | D28: 2 | E28: nr | F28: 9000 | G28: =D28*F28 -> 18000
C30: Carefully remove existing doors between G128B-G128C and G128B-G128A, and set aside in store for re-use by Landlord if required | D30: 2 | E30: nr | F30: 1200 | G30: =D30*F30 -> 2400
C32: Take out glazed screen and set aside for reuse by Landlord - Proposed doorway to write up area | D32: 1 | E32: item | F32: 750 | G32: =D32*F32 -> 750
F34: To Elemental Cost Plan Summary - Level 2 | G34: =SUM(G14:G32) -> 46967
B36: 2 | C36: Strip Out (services)
C38: Isolate and remove gas pipework / services | D38: 1 | E38: item | F38: 6000 | G38: =D38*F38 -> 6000
C40: Disconnect and remove ventilation ductwork | D40: 1 | E40: item | F40: 4000 | G40: =D40*F40 -> 4000
C42: Disconnect and remove electrical installation including light fittings and containment where required | D42: 1 | E42: item | F42: 3000 | G42: =D42*F42 -> 3000
C44: Isolate from main FA panel, disconnect and remove smoke detectors | D44: 1 | E44: item | F44: 800 | G44: =D44*F44 -> 800
C46: Isolate, disconnect and remove Crowcon system | D46: 1 | E46: item | F46: 1600 | G46: =D46*F46 -> 1600
C48: Isolate, disconnect and remove sink and cupboard from Room 2 and store for re-use / possible relocation to other side of wall later | D48: 1 | E48: item | F48: 600 | G48: =D48*F48 -> 600
C50: Isolate, disconnect and remove flow and return pipework, cap off above ceiling level | D50: 1 | E50: item | F50: 600 | G50: =D50*F50 -> 600
C52: Isolate, disconnect and remove services from store cupboards | D52: 1 | E52: item | F52: 2000 | G52: =D52*F52 -> 2000
F54: To Elemental Cost Plan Summary - Level 2 | G54: =SUM(G38:G52) -> 18600

Sheet 2.0.2.2_Superstructure
G2: G-128 Alterations
G3: Concept Cost Plan
B5: 2.0.2.2 SUPERSTRUCTURE
B10: Item | C10: Description | D10: Qty | E10: Unit | F10: Rate | G10: Total
B12: 2.7 | C12: Internal Walls and Partitions
C14: Wall lining; double skin tape and joint ready for decoration | D14: 475 | E14: m2 | F14: 72 | G14: =D14*F14 -> 34200
C16: Infill opening between Rm2 and Rm3 where door removed | D16: 3 | E16: m2 | F16: 250 | G16: =D16*F16 -> 750
C18: Box in hydrogen pipework in Rm3 (opposite door D3 - Changing room door); extra over item above for wall lining | D18: 1 | E18: item | F18: 850 | G18: =D18*F18 -> 850
C20: New partitions; 70mm stud, 2 layers 12.5mm soundblock each side, 25mm APR jointed ready for decoration. | D20: 40 | E20: m2 | F20: 166 | G20: =D20*F20 -> 6640
F22: To Elemental Cost Plan Summary - Level 2 | G22: =SUM(G14:G20) -> 42440
B24: 2.8 | C24: Internal Doors
C26: Doorsets; single leaf; semi flush hygenic doors | D26: 5 | E26: nr | F26: 3250 | G26: =D26*F26 -> 16250
C28: Doorsets; leaf and half; semi flush hygenic doors | D28: 1 | E28: nr | F28: 4800 | G28: =D28*F28 -> 4800
C30: Doorsets; single leaf; timber to write up space | D30: 2 | E30: nr | F30: 1800 | G30: =D30*F30 -> 3600
C32: Allow for refurbishing existing doors | D32: 4 | E32: nr | F32: 400 | G32: =D32*F32 -> 1600
F34: To Elemental Cost Plan Summary - Level 2 | G34: =SUM(G24:G32) -> 26250

Sheet 2.0.2.3_Finishes
G2: G-128 Alterations
G3: Concept Cost Plan
B5: 2.0.2.3 FINISHES
B10: Item | C10: Description | D10: Qty | E10: Unit | F10: Rate | G10: Total
B12: 3.1 | C12: Wall Finishes
C14: Decorate walls to lab | D14: 475 | E14: m2 | F14: 18 | G14: =D14*F14 -> 8550
C16: Decorate walls to write up area | D16: 70 | E16: m2 | F16: 18 | G16: =D16*F16 -> 1260
F18: To Elemental Cost Plan Summary - Level 2 | G18: =SUM(G14:G16) -> 9810
B20: 3.2 | C20: Floor Finishes
C22: New sheet vinyl floor to lab | D22: 173 | E22: m2 | F22: 111 | G22: =D22*F22 -> 19203
C24: Allow for coved skirting | D24: 136 | E24: m | F24: 18 | G24: =D24*F24 -> 2448
C26: Allow for new carpet in proposed write up area | D26: 33 | E26: m2 | F26: 60 | G26: =D26*F26 -> 1980
F28: To Elemental Cost Plan Summary - Level 2 | G28: =SUM(G22:G26) -> 23631
B30: 3.3 | C30: Ceiling Finishes
C32: New metal suspended ceiling to lab | D32: 173 | E32: m2 | F32: 133 | G32: =D32*F32 -> 23009
C34: Allow for perimeter detail (tbc) | D34: 136 | E34: m | F34: 18 | G34: =D34*F34 -> 2448
C36: Assumed ceiling to write up area retained and no works required | F36: 0 | G36: =D36*F36 -> 0
F38: To Elemental Cost Plan Summary - Level 2 | G38: =SUM(G32:G34) -> 25457

Sheet 2.0.2.4_FF&E
G2: G-128 Alterations
G3: Concept Cost Plan
B5: 2.0.2.4 FITTINGS, FURNISHINGS AND EQUIPMENT
B10: Item | C10: Description | D10: Qty | E10: Unit | F10: Rate | G10: Total
C12: Furniture
C14: General allowance for furniture including lockers; step over bench; mobile benches & BIBO bins | D14: 1 | E14: item | F14: 20000 | G14: =D14*F14 -> 20000
C16: Allow for furniture for write up space | D16: 1 | E16: item | F16: 5000 | G16: =D16*F16 -> 5000
C18: Equipment
C20: Isolators; provisional allowance | D20: 4 | E20: nr | F20: 150000 | G20: =D20*F20 -> 600000
C22: Isolators; provisional allowance | D22: 1 | E22: nr | F22: 100000 | G22: =D22*F22 -> 100000
C24: Fume Hoods; assumed existing Fume Hoods are serviceable; provisional allowance made for servicing and repairs if required | D24: 1 | E24: item | F24: 20000 | G24: =D24*F24 -> 20000
C26: Allow for SF6 Testing | D26: 1 | E26: item | F26: 20000 | G26: =D26*F26 -> 20000
F29: To Elemental Cost Plan Summary - Level 2 | G29: =SUM(G14:G26) -> 765000

Sheet 2.0.2.5_Services
G2: G-128 Alterations
G3: Concept Cost Plan
B5: 2.0.2.5 SERVICES
B10: Item | C10: Description | D10: Qty | E10: Unit | F10: Rate | G10: Total
C12: Disposal installations
C14: Allowance for drainage connections (sinks & shower) | D14: 1 | E14: item | F14: 3000 | G14: =D14*F14 -> 3000
F16: To Elemental Cost Plan Summary - Level 2 | G16: =SUM(G13:G15) -> 3000
C18: Water installations
C20: Allowance for H&CWS installation (sink and mist shower) | D20: 1 | E20: item | F20: 3000 | G20: =D20*F20 -> 3000
C22: Take from store and reinstall sink and under cupboard unit | D22: 1 | E22: item | F22: 600 | G22: =D22*F22 -> 600
C24: Provisional allowance for mist shower | D24: 1 | E24: item | F24: 35000 | G24: =D24*F24 -> 35000
F26: To Elemental Cost Plan Summary - Level 2 | G26: =SUM(G20:G24) -> 38600
C28: Heating, Ventilation and Air Conditioning
C30: Allow for AHU maintenance / bring the system back into use | D30: 1 | E30: item | F30: 20000 | G30: =D30*F30 -> 20000
C32: Allow for complete ductwork installation to laboratory, including supply air diffusers and extract grilles | D32: 182 | E32: m2 | F32: 560 | G32: =D32*F32 -> 101920
C34: Allow for HEPA filters to extract ductwork (Bag in/bag out) | D34: 1 | E34: item | F34: 42000 | G34: =D34*F34 -> 42000
C36: BMS upgrade; provisional allowance for disconnecting existing BMS controls, provision of new control panel, interfaces with system and commissioning | D36: 1 | E36: item | F36: 50000 | G36: =D36*F36 -> 50000
C38: Allow for balancing of system | D38: 1 | E38: item | F38: 4000 | G38: =D38*F38 -> 4000
F40: To Elemental Cost Plan Summary - Level 2 | G40: =SUM(G30:G38) -> 217920
C42: Electrical installations
C44: Small power installation to lab | D44: 182 | E44: m2 | F44: 420 | G44: =D44*F44 -> 76440
C46: Lighting installation to lab | D46: 182 | E46: m2 | F46: 170 | G46: =D46*F46 -> 30940
C48: Allow for equipment connections | G48: incl above
F50: To Elemental Cost Plan Summary - Level 2 | G50: =SUM(G44:G48) -> 107380
C52: Fire and lightning protection
C54: Allow for installation of sprinkler system to lab | D54: 182 | E54: m2 | F54: 165 | G54: =D54*F54 -> 30030
F56: To Elemental Cost Plan Summary - Level 2 | G56: =SUM(G53:G54) -> 30030
C58: Communication, security and control systems
C60: Access Control to lab entrance door and write up space access | D60: 3 | E60: nr | F60: 3000 | G60: =D60*F60 -> 9000
C62: Structured cabling installation to lab and write up areas | D62: 215 | E62: m2 | F62: 45 | G62: =D62*F62 -> 9675
C64: CCTV to lab and write up areas | D64: 215 | E64: m2 | F64: 80 | G64: =D64*F64 -> 17200
C66: Fire alarm system to lab | D66: 182 | E66: m2 | F66: 85 | G66: =D66*F66 -> 15470
F68: To Elemental Cost Plan Summary - Level 2 | G68: =SUM(G60:G66) -> 51345
C70: Special installations
C72: Laboratory gas pipework installation | D72: 182 | E72: m2 | F72: 350 | G72: =D72*F72 -> 63700
F74: To Elemental Cost Plan Summary - Level 2 | G74: =SUM(G70:G72) -> 63700
C76: Builder's Work in Connection with Services
C78: Allow for forming holes; fire stopping & access hatches | D78: 0.05 | F78: =SUM(G16+G26+G40+G50+G56+G68+G74) -> 511975 | G78: =D78*F78 -> 25598.75
F80: To Elemental Cost Plan Summary - Level 2 | G80: =SUM(G78:G79) -> 25598.75

Sheet 2.0.2.9 Prelims and Staff
G2: G-128 Alterations
G3: Concept Cost Plan
B5: 2.0.2.9 CONTRACTOR'S PRELIMINARIES AND STAFF
B10: Item | C10: Description | D10: Qty | E10: Unit | F10: Rate | G10: Total
C12: Temporary Works
C14: Allow for temporary protection to retained equipment and common areas for the duration of the works | D14: 1 | E14: item | F14: 10000 | G14: =D14*F14 -> 10000
C16: Allow for temporary lighting | D16: 1 | E16: item | F16: 500 | G16: =D16*F16 -> 500
F18: To Elemental Cost Plan Summary - Level 2 | G18: =SUM(G14:G17) -> 10500
C20: Site Welfare and Accommodation
C22: Welfare and accommodation provided during the construction phase | D22: 21 | E22: wks | F22: 1000 | G22: =D22*F22 -> 21000
F24: To Elemental Cost Plan Summary - Level 2 | G24: =SUM(G22) -> 21000
C26: Design and Construction Management
C28: Surveys | D28: 1 | E28: item | F28: 20000 | G28: =D28*F28 -> 20000
C30: Concept and Co-Ordinated Design [RIBA 2/3] - Contractor's Design including PM and Commercial input | D30: 1 | E30: item | F30: 80000 | G30: =D30*F30 -> 80000
C32: Detailed Design [RIBA 4] - Contractor's Design including PM and Commercial input | D32: 1 | E32: item | F32: 44000 | G32: =D32*F32 -> 44000
C34: Construction Stage Resourcing [RIBA 5]
C36: People and Expenses | D36: 22 | E36: wks | F36: 8500 | G36: =D36*F36 -> 187000
F38: To Elemental Cost Plan Summary - Level 2 | G38: =SUM(G28:G36) -> 331000

Sheet 2.0.2.11 Professional Services
G2: G-128 Alterations
G3: Concept Cost Plan
B5: 2.0.2.11 PROFESSIONAL SERVICES
B10: Item | C10: Description | D10: Qty | E10: Unit | F10: Rate | G10: Total
C12: Project Management
C13: Pre Contract (av 1 day per week) | D13: 33 | E13: wks | F13: 600 | G13: =D13*F13 -> 19800
C14: Post Contract (av 1.5 days per week) | D14: 22 | E14: wks | F14: =600*1.5 -> 900 | G14: =D14*F14 -> 19800
C15: Defects Period | D15: 10 | E15: Days | F15: 600 | G15: =D15*F15 -> 6000
C18: Design Support
C20: Pre Contract | D20: 1 | E20: item | F20: 10000 | G20: =D20*F20 -> 10000
C22: Commercial Support & Contract Administration
C24: Pre Contract | D24: 1 | E24: item | F24: 35000 | G24: =D24*F24 -> 35000
C26: Post Contract | D26: 22 | E26: wks | F26: 2100 | G26: =D26*F26 -> 46200
C28: Contract close & Final Certificate | D28: 1 | E28: item | F28: 5000 | G28: =D28*F28 -> 5000
F30: To Elemental Cost Plan Summary - Level 2 | G30: =SUM(G12:G28) -> 141800

Sheet 2.0.2.12 Client Equipment
G2: G-128 Alterations
G3: Concept Cost Plan
B5: 2.0.2.12 EQUIPMENT (SUPPLIED AND INSTALLED BY THE CLIENT)
B10: Item | C10: Description | D10: Qty | E10: Unit | F10: Rate | G10: Total
C12: Equipment
C14: Equipment; refer to Equipment list "Equipment List Costs for scoping 5 Aug" | D14: 1 | E14: item | F14: 1975045 | G14: =D14*F14 -> 1975045
F18: To Elemental Cost Plan Summary - Level 2 | G18: =SUM(G14:G17) -> 1975045

Sheet END
